Workbook

Sheet NGO Scorecard Dashboard
A2: ECO-HEALTH SITE ASSESSMENT DASHBOARD
A4: Partner NGO Name: | B4: [Enter NGO Name]
A5: Assessment Location / Site: | B5: [Enter Location Name, State]
A6: Assessment Date: | B6: 2026-08-26
A9: Pillar / Parameter | B9: Assigned Weight | C9: Calculated Score (0-100) | D9: Weighted Contribution | E9: Data Source / Method Summary
A10: 1. Soil Health | B10: 0.2 | C10: ='Soil Health'!C13 -> 66.666667 | D10: =B10*C10 -> 13.333333 | E10: Digital NPK/pH probe + Tea Bag Index + Crop Diversification + Grazing Pressure
A11: 2. Air Quality | B11: 0.15 | C11: ='Air Quality'!C11 -> 75 | D11: =B11*C11 -> 11.25 | E11: IoT PM2.5/PM10 sensors + Lichen bio-indicator mapping
A12: 3. Water Quality | B12: 0.2 | C12: ='Water Quality'!C11 -> 75 | D12: =B12*C12 -> 15 | E12: Handheld TDS/DO meters + Macroinvertebrate kick sampling
A13: 4. Biodiversity | B13: 0.2 | C13: =Biodiversity!C11 -> 75 | D13: =B13*C13 -> 15 | E13: 10x10m Quadrats (Shannon Index) + eBird/iNaturalist audits
A14: 5. Energy Footprint | B14: 0.125 | C14: ='Energy Footprint'!C11 -> 56.25 | D14: =B14*C14 -> 7.03125 | E14: Renewable Adoption Ratio + Biomass efficiency audits
A15: 6. Materials & Waste | B15: 0.125 | C15: ='Materials & Waste'!C11 -> 75 | D15: =B15*C15 -> 9.375 | E15: 7-Day segregation audit (Weight basis) & Diversion metrics
A16: TOTAL OVERALL ECO-HEALTH INDEX | B16: =SUM(B10:B15) -> 1 | D16: =SUM(D10:D15) -> 70.989583
A19: Eco-Health Rating Scale
A20: Index Range | B20: Ecological Health Status | C20: Action Recommended
A21: 85% - 100% | B21: Excellent / Pristine | C21: Conservation & Protection; serve as regional seed/ecological bank.
A22: 65% - 84.9% | B22: Good / Stable | C22: Continuous monitoring; introduce minor sustainable management practices.
A23: 45% - 64.9% | B23: Degrading / Vulnerable | C23: Active restoration intervention required; identify localized stressors.
A24: 0% - 44.9% | B24: Critical / Severely Damaged | C24: Immediate emergency ecological rehabilitation; strict enforcement needed.

Sheet Soil Health
A2: Ecosystem Measurement Framework: Soil Health
A5: Specific Indicator Metric | B5: Unit of Measure | C5: Target Baseline (Healthy) | D5: Field Assessment Method | E5: NGO Reported Score (0-100)
A6: Bulk Density (Soil Compaction) | B6: g/cm3 | C6: < 1.30 g/cm3 | D6: Core sampler method (Dry soil wt / volume) | E6: 75
A7: Soil Organic Carbon (SOC) | B7: % | C7: > 0.75% (Indian Target) | D7: Walkley-Black field kit / Lab validation | E7: 75
A8: pH Level Equilibrium | B8: pH Scale | C8: 6.5 - 7.5 | D8: Handheld digital electrode probe | E8: 75
A9: Microbial Activity (TBI) | B9: Decomp Rate | C9: High mass loss over 90 days | D9: Tea Bag Index standard burial method | E9: 75
A10: Crop Diversification Index (Shannon) | B10: Index (0-100 normalized) | C10: > 60 (Good diversification) | D10: Shannon-Weiner Index on seasonal crop area data — see 'Diversity & Ratio Indices' tab | E10: ='Diversity & Ratio Indices'!C40 -> 0
A11: Livestock Grazing Pressure Ratio | B11: Ratio (normalized 0-100) | C11: Stocking density <= carrying capacity | D11: Stocking density / recommended carrying capacity — see 'Diversity & Ratio Indices' tab | E11: ='Diversity & Ratio Indices'!C61 -> 100
A13: Pillar Average Score | C13: =AVERAGE(E6:E11) -> 66.666667

Sheet Air Quality
A2: Ecosystem Measurement Framework: Air Quality
A5: Specific Indicator Metric | B5: Unit of Measure | C5: Target Baseline (Healthy) | D5: Field Assessment Method | E5: NGO Reported Score (0-100)
A6: Particulate Matter (PM2.5) | B6: µg/m³ | C6: < 40 µg/m³ (CPCB Annual) | D6: Calibrated Laser PM Sensor (e.g., PMS5003) | E6: 75
A7: Particulate Matter (PM10) | B7: µg/m³ | C7: < 60 µg/m³ (CPCB Annual) | D7: Low-cost ambient outdoor monitoring unit | E7: 75
A8: Nitrogen Dioxide (NO2) | B8: µg/m³ | C8: < 40 µg/m³ | D8: Electrochemical gas sensor / Passive tubes | E8: 75
A9: Lichen Bio-Indicator Cover | B9: % grid cover | C9: > 40% tree trunk surface | D9: 10x10cm clear grid mesh overlay count | E9: 75
A11: Pillar Average Score | C11: =AVERAGE(E6:E9) -> 75

Sheet Water Quality
A2: Ecosystem Measurement Framework: Water Quality
A5: Specific Indicator Metric | B5: Unit of Measure | C5: Target Baseline (Healthy) | D5: Field Assessment Method | E5: NGO Reported Score (0-100)
A6: Total Dissolved Solids (TDS) | B6: mg/L | C6: 100 - 500 mg/L | D6: Digital TDS conductivity pen tester | E6: 75
A7: Dissolved Oxygen (DO) | B7: mg/L | C7: > 5.0 mg/L (Class A/B water) | D7: Winkler colorimetric kit / DO optical probe | E7: 75
A8: Phosphate Contamination | B8: mg/L | C8: < 0.1 mg/L (Prevents bloom) | D8: Chemical comparator visual test kit | E8: 75
A9: Macroinvertebrate Biotic Index | B9: Index Score | C9: > 7.0 (Pollution sensitive) | D9: Kick-net sampling in shallow running water | E9: 75
A11: Pillar Average Score | C11: =AVERAGE(E6:E9) -> 75

Sheet Biodiversity
A2: Ecosystem Measurement Framework: Biodiversity
A5: Specific Indicator Metric | B5: Unit of Measure | C5: Target Baseline (Healthy) | D5: Field Assessment Method | E5: NGO Reported Score (0-100)
A6: Native Floral Richness | B6: Species count | C6: Verify against regional baseline | D6: 10x10m quadrat inventory audit | E6: 75
A7: Shannon-Weiner Index (H') | B7: Index Value | C7: > 2.5 (Stable diversity) | D7: Calculated from quadrat distribution counts | E7: 75
A8: Avian Functional Diversity | B8: Species count | C8: High insectivore/frugivore ratio | D8: Fixed 15-min point counts log on eBird | E8: 75
A9: Canopy / Ground Cover Density | B9: % area | C9: > 33% total structural canopy | D9: Densiometer / smartphone micro-lux mapping | E9: 75
A11: Pillar Average Score | C11: =AVERAGE(E6:E9) -> 75

Sheet Energy Footprint
A2: Ecosystem Measurement Framework: Energy Footprint
A5: Specific Indicator Metric | B5: Unit of Measure | C5: Target Baseline (Healthy) | D5: Field Assessment Method | E5: NGO Reported Score (0-100)
A6: Renewable Energy Adoption Ratio | B6: % (normalized 0-100) | C6: > 50% localized footprint | D6: Renewable capacity or households / total — see 'Diversity & Ratio Indices' tab | E6: ='Diversity & Ratio Indices'!C79 -> 0
A7: Biomass Thermal Efficiency | B7: kg fuel/hr | C7: < 1.5 kg/hr per household | D7: Controlled Water Boiling Test (WBT) logs | E7: 75
A8: Per Capita Grid Intensity | B8: kWh/month | C8: Optimize below regional caps | D8: Monthly electricity bill tracking tables | E8: 75
A9: Passive Solar / Shade Fraction | B9: % buildings | C9: > 40% structural elements | D9: Thermal imaging / shade path blueprints | E9: 75
A11: Pillar Average Score | C11: =AVERAGE(E6:E9) -> 56.25

Sheet Materials & Waste
A2: Ecosystem Measurement Framework: Materials & Waste
A5: Specific Indicator Metric | B5: Unit of Measure | C5: Target Baseline (Healthy) | D5: Field Assessment Method | E5: NGO Reported Score (0-100)
A6: Per Capita Waste Generation | B6: kg/capita/day | C6: < 0.4 kg/day | D6: Daily collection spring balance audit | E6: 75
A7: Organic Source Segregation | B7: % by weight | C7: > 90% purity of organic bin | D7: Random audit sorting & physical weighing | E7: 75
A8: Landfill Diversion Rate | B8: % diverted | C8: > 75% recycled/composted | D8: (Composted + Recycled wt) / Total wt | E8: 75
A9: Single-Use Plastic Footprint | B9: Items/week | C9: Target: 0 items | D9: Count of unrecyclable films/MLP in waste stream | E9: 75
A11: Pillar Average Score | C11: =AVERAGE(E6:E9) -> 75

Sheet Diversity & Ratio Indices
A2: Diversity & Ratio-Based Indices
A4: These indices replace binary yes/no ratings with a continuous 0-100 score, so a real trajectory (e.g. 1 crop -> 22 crops) shows up as a gradient rather than two identical 'multicrop' flags.
A6: 1. Crop Diversification Index (Shannon-Weiner)
A7: Enter every crop grown this season and its area below (same unit throughout, e.g. acres). The index recalculates automatically as rows are filled in each season.
A9: Crop Name | B9: Area (acres) | C9: Proportion (p) | D9: p x ln(p)
B10: 0 | C10: =IF($B$35=0,0,B10/$B$35) -> 0 | D10: =IF(C10=0,0,C10*LN(C10)) -> 0
B11: 0 | C11: =IF($B$35=0,0,B11/$B$35) -> 0 | D11: =IF(C11=0,0,C11*LN(C11)) -> 0
B12: 0 | C12: =IF($B$35=0,0,B12/$B$35) -> 0 | D12: =IF(C12=0,0,C12*LN(C12)) -> 0
B13: 0 | C13: =IF($B$35=0,0,B13/$B$35) -> 0 | D13: =IF(C13=0,0,C13*LN(C13)) -> 0
B14: 0 | C14: =IF($B$35=0,0,B14/$B$35) -> 0 | D14: =IF(C14=0,0,C14*LN(C14)) -> 0
B15: 0 | C15: =IF($B$35=0,0,B15/$B$35) -> 0 | D15: =IF(C15=0,0,C15*LN(C15)) -> 0
B16: 0 | C16: =IF($B$35=0,0,B16/$B$35) -> 0 | D16: =IF(C16=0,0,C16*LN(C16)) -> 0
B17: 0 | C17: =IF($B$35=0,0,B17/$B$35) -> 0 | D17: =IF(C17=0,0,C17*LN(C17)) -> 0
B18: 0 | C18: =IF($B$35=0,0,B18/$B$35) -> 0 | D18: =IF(C18=0,0,C18*LN(C18)) -> 0
B19: 0 | C19: =IF($B$35=0,0,B19/$B$35) -> 0 | D19: =IF(C19=0,0,C19*LN(C19)) -> 0
B20: 0 | C20: =IF($B$35=0,0,B20/$B$35) -> 0 | D20: =IF(C20=0,0,C20*LN(C20)) -> 0
B21: 0 | C21: =IF($B$35=0,0,B21/$B$35) -> 0 | D21: =IF(C21=0,0,C21*LN(C21)) -> 0
... B34: 0 | C34: =IF($B$35=0,0,B34/$B$35) -> 0 | D34: =IF(C34=0,0,C34*LN(C34)) -> 0
A35: Total Area | B35: =SUM(B10:B34) -> 0
A37: Shannon Diversity Index (H') | C37: =-SUM(D10:D34) -> 0
A38: Simpson's Diversity Index (1-D) | C38: =1-SUMPRODUCT(C10:C34,C10:C34) -> 1
A39: Number of Crops Recorded | C39: =COUNTIF(B10:B34,">0") -> 0
A40: Normalized Score (0-100) | C40: =MIN(100,(C37/3)*100) -> 0
A42: Interpretation
A43: Shannon Index (H') Range | B43: Status
A44: 0.00 | B44: Pure monocrop
A45: 0.01 - 0.69 | B45: Low diversity (token multicropping, e.g. 2 crops at 90/10 split)
A46: 0.70 - 1.60 | B46: Moderate diversification
A47: 1.61 - 2.50 | B47: Good diversification
A48: > 2.50 | B48: High diversification (traditional polyculture level, approaching 20+ crops)
A52: 2. Livestock Grazing Pressure Ratio
A53: Enter total grazing livestock (converted to Livestock Units, LU), the grazing land area, and the recommended carrying capacity for this ecosystem type (consult regional agriculture/forestry norms; typical semi-arid India range is 2-4 LU/hectare).
A55: Total Livestock Units (LU) Grazing Site | C55: 0
A56: Grazing Land Area (hectares) | C56: 0
A57: Recommended Carrying Capacity (LU/hectare) | C57: 3
A59: Actual Stocking Density (LU/ha) | C59: =IF(C56=0,0,C55/C56) -> 0
A60: Grazing Pressure Ratio (density / capacity) | C60: =IF(C57=0,0,C59/C57) -> 0
A61: Normalized Score (0-100) | C61: =IF(C57=0,0,MAX(0,MIN(100,100-(C60-1)*100))) -> 100
A63: Interpretation
A64: Grazing Pressure Ratio | B64: Status
...
